Workbook
Name SegmentaçãodeDados_Categoria_de_despesa: #N/A
Name SegmentaçãodeDados_Data_do_Pagamento___Compra: #N/A
Name SegmentaçãodeDados_Mês: #N/A
Name SegmentaçãodeDados_Tag: #N/A

Sheet TRANSAÇÕES
A2: Fluxo de caixa
A3: Descrição | B3: Caixa | C3: Tag | D3: Forma de Pagamento | E3: Valor | F3: Data de Compra | G3: Data do Pagamento / Compra | H3: Categoria de despesa | I3: Mês | J3: Status
A4: Farmácia | B4: Despesa | C4: Saúde | D4: Débito | E4: 12.34 | F4: 45293 | G4: 45293 | H4: =IFERROR(VLOOKUP(Tabela1[[#This Row],[Tag]],TAGS!$J$1:$K$11,2,0),"") -> Essencial | I4: =IF(G4="","",TEXT(G4,"mmmm")) -> janeiro | J4: =IF(Tabela1[[#This Row],[Caixa]]="Receita","Recebido",IF(F4="","",IF(G4="","",IF(G4<F4,"Pago atrasado",IF(Tabela1[[#This Row],[Data do Pagamento / Compra]]>Tabela1[[#This Row],[Data de Compra]],"Pago","Pago"))))) -> Pago
A5: Giassi | B5: Despesa | C5: Mercado | D5: Débito | E5: 139.93 | F5: 45293 | G5: 45293 | H5: =IFERROR(VLOOKUP(Tabela1[[#This Row],[Tag]],TAGS!$J$1:$K$11,2,0),"") -> Essencial | I5: =IF(G5="","",TEXT(G5,"mmmm")) -> janeiro | J5: =IF(Tabela1[[#This Row],[Caixa]]="Receita","Recebido",IF(F5="","",IF(G5="","",IF(G5<F5,"Pago atrasado",IF(Tabela1[[#This Row],[Data do Pagamento / Compra]]>Tabela1[[#This Row],[Data de Compra]],"Pago","Pago"))))) -> Pago
A6: Remédio Catarinense | B6: Despesa | C6: Saúde | D6: Débito | E6: 87 | F6: 45293 | G6: 45293 | H6: =IFERROR(VLOOKUP(Tabela1[[#This Row],[Tag]],TAGS!$J$1:$K$11,2,0),"") -> Essencial | I6: =IF(G6="","",TEXT(G6,"mmmm")) -> janeiro | J6: =IF(Tabela1[[#This Row],[Caixa]]="Receita","Recebido",IF(F6="","",IF(G6="","",IF(G6<F6,"Pago atrasado",IF(Tabela1[[#This Row],[Data do Pagamento / Compra]]>Tabela1[[#This Row],[Data de Compra]],"Pago","Pago"))))) -> Pago
A7: Vitorino | B7: Despesa | C7: Mercado | D7: Débito | E7: 34.97 | F7: 45293 | G7: 45293 | H7: =IFERROR(VLOOKUP(Tabela1[[#This Row],[Tag]],TAGS!$J$1:$K$11,2,0),"") -> Essencial | I7: =IF(G7="","",TEXT(G7,"mmmm")) -> janeiro | J7: =IF(Tabela1[[#This Row],[Caixa]]="Receita","Recebido",IF(F7="","",IF(G7="","",IF(G7<F7,"Pago atrasado",IF(Tabela1[[#This Row],[Data do Pagamento / Compra]]>Tabela1[[#This Row],[Data de Compra]],"Pago","Pago"))))) -> Pago
A8: Restaurante | B8: Despesa | C8: Lazer | D8: Débito | E8: 40 | F8: 45293 | G8: 45293 | H8: =IFERROR(VLOOKUP(Tabela1[[#This Row],[Tag]],TAGS!$J$1:$K$11,2,0),"") -> Não essencial | I8: =IF(G8="","",TEXT(G8,"mmmm")) -> janeiro | J8: =IF(Tabela1[[#This Row],[Caixa]]="Receita","Recebido",IF(F8="","",IF(G8="","",IF(G8<F8,"Pago atrasado",IF(Tabela1[[#This Row],[Data do Pagamento / Compra]]>Tabela1[[#This Row],[Data de Compra]],"Pago","Pago"))))) -> Pago
A9: POP | B9: Despesa | C9: Transporte | D9: Débito | E9: 6.9 | F9: 45294 | G9: 45293 | H9: =IFERROR(VLOOKUP(Tabela1[[#This Row],[Tag]],TAGS!$J$1:$K$11,2,0),"") -> Essencial | I9: =IF(G9="","",TEXT(G9,"mmmm")) -> janeiro | J9: =IF(Tabela1[[#This Row],[Caixa]]="Receita","Recebido",IF(F9="","",IF(G9="","",IF(G9<F9,"Pago atrasado",IF(Tabela1[[#This Row],[Data do Pagamento / Compra]]>Tabela1[[#This Row],[Data de Compra]],"Pago","Pago"))))) -> Pago atrasado
A10: POP | B10: Despesa | C10: Transporte | D10: Débito | E10: 7.6 | F10: 45294 | G10: 45294 | H10: =IFERROR(VLOOKUP(Tabela1[[#This Row],[Tag]],TAGS!$J$1:$K$11,2,0),"") -> Essencial | I10: =IF(G10="","",TEXT(G10,"mmmm")) -> janeiro | J10: =IF(Tabela1[[#This Row],[Caixa]]="Receita","Recebido",IF(F10="","",IF(G10="","",IF(G10<F10,"Pago atrasado",IF(Tabela1[[#This Row],[Data do Pagamento / Compra]]>Tabela1[[#This Row],[Data de Compra]],"Pago","Pago"))))) -> Pago
A11: Giassi | B11: Despesa | C11: Mercado | D11: Débito | E11: 151.37 | F11: 45294 | G11: 45294 | H11: =IFERROR(VLOOKUP(Tabela1[[#This Row],[Tag]],TAGS!$J$1:$K$11,2,0),"") -> Essencial | I11: =IF(G11="","",TEXT(G11,"mmmm")) -> janeiro | J11: =IF(Tabela1[[#This Row],[Caixa]]="Receita","Recebido",IF(F11="","",IF(G11="","",IF(G11<F11,"Pago atrasado",IF(Tabela1[[#This Row],[Data do Pagamento / Compra]]>Tabela1[[#This Row],[Data de Compra]],"Pago","Pago"))))) -> Pago
A12: Aluguel | B12: Despesa | C12: Moradia | D12: Boleto | E12: 950 | F12: 45296 | G12: 45296 | H12: =IFERROR(VLOOKUP(Tabela1[[#This Row],[Tag]],TAGS!$J$1:$K$11,2,0),"") -> Essencial | I12: =IF(G12="","",TEXT(G12,"mmmm")) -> janeiro | J12: =IF(Tabela1[[#This Row],[Caixa]]="Receita","Recebido",IF(F12="","",IF(G12="","",IF(G12<F12,"Pago atrasado",IF(Tabela1[[#This Row],[Data do Pagamento / Compra]]>Tabela1[[#This Row],[Data de Compra]],"Pago","Pago"))))) -> Pago
A13: Cooper | B13: Despesa | C13: Mercado | D13: Débito | E13: 74.14 | F13: 45296 | G13: 45296 | H13: =IFERROR(VLOOKUP(Tabela1[[#This Row],[Tag]],TAGS!$J$1:$K$11,2,0),"") -> Essencial | I13: =IF(G13="","",TEXT(G13,"mmmm")) -> janeiro | J13: =IF(Tabela1[[#This Row],[Caixa]]="Receita","Recebido",IF(F13="","",IF(G13="","",IF(G13<F13,"Pago atrasado",IF(Tabela1[[#This Row],[Data do Pagamento / Compra]]>Tabela1[[#This Row],[Data de Compra]],"Pago","Pago"))))) -> Pago
A14: Super Dog | B14: Despesa | C14: Lazer | D14: Débito | E14: 24 | F14: 45296 | G14: 45296 | H14: =IFERROR(VLOOKUP(Tabela1[[#This Row],[Tag]],TAGS!$J$1:$K$11,2,0),"") -> Não essencial | I14: =IF(G14="","",TEXT(G14,"mmmm")) -> janeiro | J14: =IF(Tabela1[[#This Row],[Caixa]]="Receita","Recebido",IF(F14="","",IF(G14="","",IF(G14<F14,"Pago atrasado",IF(Tabela1[[#This Row],[Data do Pagamento / Compra]]>Tabela1[[#This Row],[Data de Compra]],"Pago","Pago"))))) -> Pago
A15: POP | B15: Despesa | C15: Transporte | D15: Débito | E15: 8.3 | F15: 45296 | G15: 45296 | H15: =IFERROR(VLOOKUP(Tabela1[[#This Row],[Tag]],TAGS!$J$1:$K$11,2,0),"") -> Essencial | I15: =IF(G15="","",TEXT(G15,"mmmm")) -> janeiro | J15: =IF(Tabela1[[#This Row],[Caixa]]="Receita","Recebido",IF(F15="","",IF(G15="","",IF(G15<F15,"Pago atrasado",IF(Tabela1[[#This Row],[Data do Pagamento / Compra]]>Tabela1[[#This Row],[Data de Compra]],"Pago","Pago"))))) -> Pago
... A273: COOPER | B273: Despesa | C273: Mercado | D273: Alelo | E273: 75.18 | F273: 45366 | G273: 45388 | H273: =IFERROR(VLOOKUP(Tabela1[[#This Row],[Tag]],TAGS!$J$1:$K$11,2,0),"") -> Essencial | I273: =IF(G273="","",TEXT(G273,"mmmm")) -> abril | J273: =IF(Tabela1[[#This Row],[Caixa]]="Receita","Recebido",IF(F273="","",IF(G273="","",IF(G273<F273,"Pago atrasado",IF(Tabela1[[#This Row],[Data do Pagamento / Compra]]>Tabela1[[#This Row],[Data de Compra]],"Pago","Pago"))))) -> Pago
A274: Livro Av. de Mike | B274: Despesa | C274: Lazer | D274: C6 Crédito | E274: 55.9 | F274: 45366 | H274: =IFERROR(VLOOKUP(Tabela1[[#This Row],[Tag]],TAGS!$J$1:$K$11,2,0),"") -> Não essencial | I274: =IF(G274="","",TEXT(G274,"mmmm")) | J274: =IF(Tabela1[[#This Row],[Caixa]]="Receita","Recebido",IF(F274="","",IF(G274="","",IF(G274<F274,"Pago atrasado",IF(Tabela1[[#This Row],[Data do Pagamento / Compra]]>Tabela1[[#This Row],[Data de Compra]],"Pago","Pago")))))
A275: Posto | B275: Despesa | C275: Lazer | D275: Débito | E275: 17.98 | F275: 45367 | G275: 45367 | H275: =IFERROR(VLOOKUP(Tabela1[[#This Row],[Tag]],TAGS!$J$1:$K$11,2,0),"") -> Não essencial | I275: =IF(G275="","",TEXT(G275,"mmmm")) -> março | J275: =IF(Tabela1[[#This Row],[Caixa]]="Receita","Recebido",IF(F275="","",IF(G275="","",IF(G275<F275,"Pago atrasado",IF(Tabela1[[#This Row],[Data do Pagamento / Compra]]>Tabela1[[#This Row],[Data de Compra]],"Pago","Pago"))))) -> Pago
A276: POP | B276: Despesa | C276: Transporte | D276: Débito | E276: 18.68 | F276: 45369 | G276: 45369 | H276: =IFERROR(VLOOKUP(Tabela1[[#This Row],[Tag]],TAGS!$J$1:$K$11,2,0),"") -> Essencial | I276: =IF(G276="","",TEXT(G276,"mmmm")) -> março | J276: =IF(Tabela1[[#This Row],[Caixa]]="Receita","Recebido",IF(F276="","",IF(G276="","",IF(G276<F276,"Pago atrasado",IF(Tabela1[[#This Row],[Data do Pagamento / Compra]]>Tabela1[[#This Row],[Data de Compra]],"Pago","Pago"))))) -> Pago
A277: Academia | B277: Despesa | C277: Saúde | D277: Hipercard Crédito | E277: 109 | F277: 45367 | G277: 45392 | H277: =IFERROR(VLOOKUP(Tabela1[[#This Row],[Tag]],TAGS!$J$1:$K$11,2,0),"") -> Essencial | I277: =IF(G277="","",TEXT(G277,"mmmm")) -> abril | J277: =IF(Tabela1[[#This Row],[Caixa]]="Receita","Recebido",IF(F277="","",IF(G277="","",IF(G277<F277,"Pago atrasado",IF(Tabela1[[#This Row],[Data do Pagamento / Compra]]>Tabela1[[#This Row],[Data de Compra]],"Pago","Pago"))))) -> Pago
A278: Amazon Prime | B278: Despesa | C278: Lazer | D278: Hipercard Crédito | E278: 19.9 | F278: 45367 | G278: 45392 | H278: =IFERROR(VLOOKUP(Tabela1[[#This Row],[Tag]],TAGS!$J$1:$K$11,2,0),"") -> Não essencial | I278: =IF(G278="","",TEXT(G278,"mmmm")) -> abril | J278: =IF(Tabela1[[#This Row],[Caixa]]="Receita","Recebido",IF(F278="","",IF(G278="","",IF(G278<F278,"Pago atrasado",IF(Tabela1[[#This Row],[Data do Pagamento / Compra]]>Tabela1[[#This Row],[Data de Compra]],"Pago","Pago"))))) -> Pago
A279: POP | B279: Despesa | C279: Transporte | D279: Hipercard Crédito | E279: 17.3 | F279: 45370 | G279: 45392 | H279: =IFERROR(VLOOKUP(Tabela1[[#This Row],[Tag]],TAGS!$J$1:$K$11,2,0),"") -> Essencial | I279: =IF(G279="","",TEXT(G279,"mmmm")) -> abril | J279: =IF(Tabela1[[#This Row],[Caixa]]="Receita","Recebido",IF(F279="","",IF(G279="","",IF(G279<F279,"Pago atrasado",IF(Tabela1[[#This Row],[Data do Pagamento / Compra]]>Tabela1[[#This Row],[Data de Compra]],"Pago","Pago"))))) -> Pago
A280: POP | B280: Despesa | C280: Transporte | D280: Hipercard Crédito | E280: 12.15 | F280: 45370 | G280: 45392 | H280: =IFERROR(VLOOKUP(Tabela1[[#This Row],[Tag]],TAGS!$J$1:$K$11,2,0),"") -> Essencial | I280: =IF(G280="","",TEXT(G280,"mmmm")) -> abril | J280: =IF(Tabela1[[#This Row],[Caixa]]="Receita","Recebido",IF(F280="","",IF(G280="","",IF(G280<F280,"Pago atrasado",IF(Tabela1[[#This Row],[Data do Pagamento / Compra]]>Tabela1[[#This Row],[Data de Compra]],"Pago","Pago"))))) -> Pago
A281: POP | B281: Despesa | C281: Transporte | D281: Hipercard Crédito | E281: 17.2 | F281: 45370 | G281: 45392 | H281: =IFERROR(VLOOKUP(Tabela1[[#This Row],[Tag]],TAGS!$J$1:$K$11,2,0),"") -> Essencial | I281: =IF(G281="","",TEXT(G281,"mmmm")) -> abril | J281: =IF(Tabela1[[#This Row],[Caixa]]="Receita","Recebido",IF(F281="","",IF(G281="","",IF(G281<F281,"Pago atrasado",IF(Tabela1[[#This Row],[Data do Pagamento / Compra]]>Tabela1[[#This Row],[Data de Compra]],"Pago","Pago"))))) -> Pago
A282: POP | B282: Despesa | C282: Transporte | D282: Hipercard Crédito | E282: 9.45 | F282: 45371 | G282: 45392 | H282: =IFERROR(VLOOKUP(Tabela1[[#This Row],[Tag]],TAGS!$J$1:$K$11,2,0),"") -> Essencial | I282: =IF(G282="","",TEXT(G282,"mmmm")) -> abril | J282: =IF(Tabela1[[#This Row],[Caixa]]="Receita","Recebido",IF(F282="","",IF(G282="","",IF(G282<F282,"Pago atrasado",IF(Tabela1[[#This Row],[Data do Pagamento / Compra]]>Tabela1[[#This Row],[Data de Compra]],"Pago","Pago"))))) -> Pago
A283: POP | B283: Despesa | C283: Transporte | D283: Hipercard Crédito | E283: 33 | F283: 45371 | G283: 45392 | H283: =IFERROR(VLOOKUP(Tabela1[[#This Row],[Tag]],TAGS!$J$1:$K$11,2,0),"") -> Essencial | I283: =IF(G283="","",TEXT(G283,"mmmm")) -> abril | J283: =IF(Tabela1[[#This Row],[Caixa]]="Receita","Recebido",IF(F283="","",IF(G283="","",IF(G283<F283,"Pago atrasado",IF(Tabela1[[#This Row],[Data do Pagamento / Compra]]>Tabela1[[#This Row],[Data de Compra]],"Pago","Pago"))))) -> Pago
A284: POP | B284: Despesa | C284: Transporte | D284: Hipercard Crédito | E284: 13.1 | F284: 45371 | G284: 45392 | H284: =IFERROR(VLOOKUP(Tabela1[[#This Row],[Tag]],TAGS!$J$1:$K$11,2,0),"") -> Essencial | I284: =IF(G284="","",TEXT(G284,"mmmm")) -> abril | J284: =IF(Tabela1[[#This Row],[Caixa]]="Receita","Recebido",IF(F284="","",IF(G284="","",IF(G284<F284,"Pago atrasado",IF(Tabela1[[#This Row],[Data do Pagamento / Compra]]>Tabela1[[#This Row],[Data de Compra]],"Pago","Pago"))))) -> Pago
A285: POP | B285: Despesa | C285: Transporte | D285: Hipercard Crédito | E285: 13.98 | F285: 45372 | G285: 45392 | H285: =IFERROR(VLOOKUP(Tabela1[[#This Row],[Tag]],TAGS!$J$1:$K$11,2,0),"") -> Essencial | I285: =IF(G285="","",TEXT(G285,"mmmm")) -> abril | J285: =IF(Tabela1[[#This Row],[Caixa]]="Receita","Recebido",IF(F285="","",IF(G285="","",IF(G285<F285,"Pago atrasado",IF(Tabela1[[#This Row],[Data do Pagamento / Compra]]>Tabela1[[#This Row],[Data de Compra]],"Pago","Pago"))))) -> Pago
A286: POP | B286: Despesa | C286: Transporte | D286: Hipercard Crédito | E286: 16.6 | F286: 45372 | G286: 45392 | H286: =IFERROR(VLOOKUP(Tabela1[[#This Row],[Tag]],TAGS!$J$1:$K$11,2,0),"") -> Essencial | I286: =IF(G286="","",TEXT(G286,"mmmm")) -> abril | J286: =IF(Tabela1[[#This Row],[Caixa]]="Receita","Recebido",IF(F286="","",IF(G286="","",IF(G286<F286,"Pago atrasado",IF(Tabela1[[#This Row],[Data do Pagamento / Compra]]>Tabela1[[#This Row],[Data de Compra]],"Pago","Pago"))))) -> Pago
... A317: POP | B317: Despesa | C317: Transporte | D317: Hipercard Crédito | E317: 15 | F317: 45385 | G317: 45392 | H317: =IFERROR(VLOOKUP(Tabela1[[#This Row],[Tag]],TAGS!$J$1:$K$11,2,0),"") -> Essencial | I317: =IF(G317="","",TEXT(G317,"mmmm")) -> abril | J317: =IF(Tabela1[[#This Row],[Caixa]]="Receita","Recebido",IF(F317="","",IF(G317="","",IF(G317<F317,"Pago atrasado",IF(Tabela1[[#This Row],[Data do Pagamento / Compra]]>Tabela1[[#This Row],[Data de Compra]],"Pago","Pago"))))) -> Pago
A318: POP | B318: Despesa | C318: Transporte | D318: Hipercard Crédito | E318: 15 | F318: 45386 | H318: =IFERROR(VLOOKUP(Tabela1[[#This Row],[Tag]],TAGS!$J$1:$K$11,2,0),"") -> Essencial | I318: =IF(G318="","",TEXT(G318,"mmmm")) | J318: =IF(Tabela1[[#This Row],[Caixa]]="Receita","Recebido",IF(F318="","",IF(G318="","",IF(G318<F318,"Pago atrasado",IF(Tabela1[[#This Row],[Data do Pagamento / Compra]]>Tabela1[[#This Row],[Data de Compra]],"Pago","Pago")))))
A319: POP | B319: Despesa | C319: Transporte | D319: Hipercard Crédito | E319: 20 | F319: 45387 | H319: =IFERROR(VLOOKUP(Tabela1[[#This Row],[Tag]],TAGS!$J$1:$K$11,2,0),"") -> Essencial | I319: =IF(G319="","",TEXT(G319,"mmmm")) | J319: =IF(Tabela1[[#This Row],[Caixa]]="Receita","Recebido",IF(F319="","",IF(G319="","",IF(G319<F319,"Pago atrasado",IF(Tabela1[[#This Row],[Data do Pagamento / Compra]]>Tabela1[[#This Row],[Data de Compra]],"Pago","Pago")))))
A320: POP | B320: Despesa | C320: Transporte | D320: Hipercard Crédito | E320: 16 | F320: 45387 | H320: =IFERROR(VLOOKUP(Tabela1[[#This Row],[Tag]],TAGS!$J$1:$K$11,2,0),"") -> Essencial | I320: =IF(G320="","",TEXT(G320,"mmmm")) | J320: =IF(Tabela1[[#This Row],[Caixa]]="Receita","Recebido",IF(F320="","",IF(G320="","",IF(G320<F320,"Pago atrasado",IF(Tabela1[[#This Row],[Data do Pagamento / Compra]]>Tabela1[[#This Row],[Data de Compra]],"Pago","Pago")))))
A321: Viagem Treking | B321: Despesa | C321: Lazer | D321: Pix | E321: 100 | F321: 45388 | G321: 45388 | H321: =IFERROR(VLOOKUP(Tabela1[[#This Row],[Tag]],TAGS!$J$1:$K$11,2,0),"") -> Não essencial | I321: =IF(G321="","",TEXT(G321,"mmmm")) -> abril | J321: =IF(Tabela1[[#This Row],[Caixa]]="Receita","Recebido",IF(F321="","",IF(G321="","",IF(G321<F321,"Pago atrasado",IF(Tabela1[[#This Row],[Data do Pagamento / Compra]]>Tabela1[[#This Row],[Data de Compra]],"Pago","Pago"))))) -> Pago
A322: Camisetas | B322: Despesa | C322: Outros | D322: Débito | E322: 69.9 | F322: 45388 | G322: 45388 | H322: =IFERROR(VLOOKUP(Tabela1[[#This Row],[Tag]],TAGS!$J$1:$K$11,2,0),"") -> Não essencial | I322: =IF(G322="","",TEXT(G322,"mmmm")) -> abril | J322: =IF(Tabela1[[#This Row],[Caixa]]="Receita","Recebido",IF(F322="","",IF(G322="","",IF(G322<F322,"Pago atrasado",IF(Tabela1[[#This Row],[Data do Pagamento / Compra]]>Tabela1[[#This Row],[Data de Compra]],"Pago","Pago"))))) -> Pago
A323: Calça | B323: Despesa | C323: Outros | D323: Débito | E323: 129 | F323: 45388 | G323: 45388 | H323: =IFERROR(VLOOKUP(Tabela1[[#This Row],[Tag]],TAGS!$J$1:$K$11,2,0),"") -> Não essencial | I323: =IF(G323="","",TEXT(G323,"mmmm")) -> abril | J323: =IF(Tabela1[[#This Row],[Caixa]]="Receita","Recebido",IF(F323="","",IF(G323="","",IF(G323<F323,"Pago atrasado",IF(Tabela1[[#This Row],[Data do Pagamento / Compra]]>Tabela1[[#This Row],[Data de Compra]],"Pago","Pago"))))) -> Pago
A324: Tenis | B324: Despesa | C324: Outros | D324: Débito | E324: 249.9 | F324: 45388 | G324: 45388 | H324: =IFERROR(VLOOKUP(Tabela1[[#This Row],[Tag]],TAGS!$J$1:$K$11,2,0),"") -> Não essencial | I324: =IF(G324="","",TEXT(G324,"mmmm")) -> abril | J324: =IF(Tabela1[[#This Row],[Caixa]]="Receita","Recebido",IF(F324="","",IF(G324="","",IF(G324<F324,"Pago atrasado",IF(Tabela1[[#This Row],[Data do Pagamento / Compra]]>Tabela1[[#This Row],[Data de Compra]],"Pago","Pago"))))) -> Pago
A325: Posto Principe | B325: Despesa | C325: Lazer | D325: Pix | E325: 29.97 | F325: 45388 | G325: 45388 | H325: =IFERROR(VLOOKUP(Tabela1[[#This Row],[Tag]],TAGS!$J$1:$K$11,2,0),"") -> Não essencial | I325: =IF(G325="","",TEXT(G325,"mmmm")) -> abril | J325: =IF(Tabela1[[#This Row],[Caixa]]="Receita","Recebido",IF(F325="","",IF(G325="","",IF(G325<F325,"Pago atrasado",IF(Tabela1[[#This Row],[Data do Pagamento / Compra]]>Tabela1[[#This Row],[Data de Compra]],"Pago","Pago"))))) -> Pago
A326: Posto Principe | B326: Despesa | C326: Lazer | D326: Pix | E326: 7.99 | F326: 45388 | G326: 45388 | H326: =IFERROR(VLOOKUP(Tabela1[[#This Row],[Tag]],TAGS!$J$1:$K$11,2,0),"") -> Não essencial | I326: =IF(G326="","",TEXT(G326,"mmmm")) -> abril | J326: =IF(Tabela1[[#This Row],[Caixa]]="Receita","Recebido",IF(F326="","",IF(G326="","",IF(G326<F326,"Pago atrasado",IF(Tabela1[[#This Row],[Data do Pagamento / Compra]]>Tabela1[[#This Row],[Data de Compra]],"Pago","Pago"))))) -> Pago
A327: COOPER | B327: Despesa | C327: Mercado | D327: Alelo | E327: 116.05 | F327: 45380 | G327: 45418 | H327: =IFERROR(VLOOKUP(Tabela1[[#This Row],[Tag]],TAGS!$J$1:$K$11,2,0),"") -> Essencial | I327: =IF(G327="","",TEXT(G327,"mmmm")) -> maio | J327: =IF(Tabela1[[#This Row],[Caixa]]="Receita","Recebido",IF(F327="","",IF(G327="","",IF(G327<F327,"Pago atrasado",IF(Tabela1[[#This Row],[Data do Pagamento / Compra]]>Tabela1[[#This Row],[Data de Compra]],"Pago","Pago"))))) -> Pago
A328: COOPER | B328: Despesa | C328: Mercado | D328: Alelo | E328: 124.59 | F328: 45388 | G328: 45418 | H328: =IFERROR(VLOOKUP(Tabela1[[#This Row],[Tag]],TAGS!$J$1:$K$11,2,0),"") -> Essencial | I328: =IF(G328="","",TEXT(G328,"mmmm")) -> maio | J328: =IF(Tabela1[[#This Row],[Caixa]]="Receita","Recebido",IF(F328="","",IF(G328="","",IF(G328<F328,"Pago atrasado",IF(Tabela1[[#This Row],[Data do Pagamento / Compra]]>Tabela1[[#This Row],[Data de Compra]],"Pago","Pago"))))) -> Pago
...

Sheet PAINEL

Sheet PLANO DE AÇÃO
A1: PLANO DE AÇÃO 5W2H
A2: 5W | F2: 2H | H2: STATUS
A3: O QUÊ? (WHAT) | B3: PORQUE? (WHY) | C3: ONDE? (WHERE) | D3: QUEM? (WHO) | E3: QUANDO? (WHEN) | F3: COMO? (HOW) | G3: QUANTO CUSTA? (HOW MUCH)
A4: Reduzir custo com cartão Hipercarde 50%.Em fevereiro foi 543$. | B4: Reduzir gastos para acelerar/aumentar investimentos. | C4: Compras desnecessárias | D4: Marcos | E4: 45388 | F4: Usar cartão apenas para programas de assinatura. | G4: 271
A5: Reduzir custo com cartão C6 20%. Em fevereiro foi 626. | B5: Reduzir gastos para acelerar/aumentar investimentos. | C5: Compras desnecessárias | D5: Marcos | E5: 45388 | F5: Usar cartão apenas para programas de assinatura. | G5: 501
A6: Reduzir gastos com transporte em 30%. Em Fevereiro foi 677$. | B6: Reduzir gastos para acelerar/aumentar investimentos | C6: Aplicativo | D6: Marcos | E6: 45388 | F6: Ir trabalhar de bike ou de Ônibus. | G6: 474
A7: Executar preenchimento da planilha diariamente. | B7: Manter organização evitando erros e perda de tempo no preenchimento | C7: Excel | D7: Marcos | E7: 45388 | F7: Todo dia a noite.
A8: Fazer planejamento de gastos mensal | B8: Evoluir controle e aumentar investimentos. | C8: Excel | D8: Marcos | E8: 45388 | F8: Mensal com revisão Quinzenal.
A9: Reduzir gastos com lazer em 20%, em fevereiro foi 539$ | B9: Reduzir gastos para acelerar/aumentar investimentos. | C9: Lazer | D9: Marcos | E9: 45388 | F9: Menos saídas e compras. | G9: 432 | H9: 272

Sheet TABELAS
AB1: =GETPIVOTDATA("Valor",$AA$4) -> 441.06 | AE1: =GETPIVOTDATA("Valor",$AD$4) -> 0
M2: =GETPIVOTDATA("Valor",$L$5) -> 441.06 | AA2: Mês | AB2: maio | AD2: Mês | AE2: maio
B3: Mês | C3: maio | F3: Mês | G3: maio | I3: Mês | J3: maio | L3: Mês | M3: maio | Q3: Mês | R3: maio | U3: Caixa | W3: Meta de gastos
U4: =GETPIVOTDATA("Valor",$T$5,"Caixa","Receita")-GETPIVOTDATA("Valor",$T$5,"Caixa","Despesa") -> 4422.844 | W4: Essencial | Y4: 0.5 | AA4: Rótulos de Linha | AB4: Soma de Valor | AD4: Rótulos de Linha | AE4: Soma de Valor
B5: Rótulos de Linha | C5: Soma de Valor | F5: Rótulos de Linha | G5: Soma de Valor | I5: Rótulos de Linha | J5: Soma de Valor | L5: Rótulos de Linha | M5: Soma de Valor | O5: Despesa | P5: =GETPIVOTDATA("Valor",$Q$5,"Caixa","Despesa") -> 441.06 | Q5: Rótulos de Linha | R5: Soma de Valor | T5: Rótulos de Linha | U5: Soma de Valor | W5: Investimento | Y5: 0.2 | AA5: Essencial | AB5: 441.06 | AD5: Total Geral
B6: Mercado | C6: 441.06 | F6: Despesa | G6: 441.06 | I6: Essencial | J6: 441.06 | L6: Essencial | M6: 441.06 | O6: Receita | P6: =GETPIVOTDATA("Valor",$Q$5,"Caixa","Receita") -> #REF! | Q6: Despesa | R6: 441.06 | T6: Despesa | U6: 19494.016 | W6: Não essencial | Y6: 0.3 | AA6: Cooper | AB6: 441.06
B7: Total Geral | C7: 441.06 | F7: Total Geral | G7: 441.06 | I7: Total Geral | J7: 441.06 | L7: Cooper | M7: 441.06 | O7: CAIXA | P7: =P6-P5 -> #REF! | Q7: Total Geral | R7: 441.06 | T7: Receita | U7: 23916.86 | AA7: Total Geral | AB7: 441.06
L8: Total Geral | M8: 441.06 | T8: Total Geral | U8: 43410.876

Sheet Planilha1
A1: Mês | B1: Despesa | C1: valor
A2: Março | B2: Condomínio | C2: 450
A3: Março | B3: Luz | C3: 300
A4: Março | B4: Internet | C4: 120
A5: Abril | B5: Aluguel | C5: 1900
A6: Abril | B6: Condomínio | C6: 485
A7: Abril | B7: Luz | C7: 285
A8: Abril | B8: Internet | C8: 120
C9: =SUM(C2:C8) -> 3660
B10: Marcos | C10: =C9/2 -> 1830
B11: Rodrigo | C11: =C9/2 -> 1830

Sheet TAGS
A1: Tags | C1: Caixa | E1: Formas de pagamento | J1: Categoria de Despesa | K1: Desc
A2: Moradia | C2: Receita | E2: Débito | J2: Moradia | K2: Essencial
A3: Mercado | C3: Despesa | E3: Crédito | J3: Mercado | K3: Essencial
A4: Transporte | C4: Investimento | E4: Pix | J4: Transporte | K4: Essencial
A5: Lazer | E5: Next | J5: Lazer | K5: Não essencial
A6: Beleza | E6: Boleto | J6: Beleza | K6: Não essencial
A7: Saúde | E7: Hipercard Crédito | J7: Saúde | K7: Essencial
A8: Educação | E8: C6 Crédito | J8: Educação | K8: Essencial
A9: Outros | E9: Alelo | J9: Outros | K9: Não essencial
A10: Salário | J10: Investimento | K10: Investimento
A11: Investimento | J11: Salário | K11: Receita
