Workbook
Name SegmentaçãodeDados_Mês: #N/A
Name SegmentaçãodeDados_Tag: #N/A

Sheet PAINEL
B9: CAIXA | C9: =G9-E9 -> 7829.58 | D9: DESPESAS | E9: =GETPIVOTDATA("Valor",TABELAS!$F$4,"Caixa","Despesa") -> 4563.26 | F9: RECEITA | G9: =GETPIVOTDATA("Valor",TABELAS!$F$4,"Caixa","Receita") -> 12392.84

Sheet TABELAS
B2: Mês | C2: (Tudo) | F2: Mês | G2: (Tudo) | I2: Mês | J2: (Tudo) | L2: Mês | M2: (Tudo)
B4: Rótulos de Linha | C4: Soma de Valor | F4: Rótulos de Linha | G4: Soma de Valor | I4: Rótulos de Linha | J4: Soma de Valor | L4: Rótulos de Linha | M4: Soma de Valor
B5: Moradia | C5: 1550 | F5: Despesa | G5: 4563.26 | I5: Essencial | J5: 2727.26 | L5: Não essencial | M5: 150
B6: Lazer | C6: 820.7 | F6: Receita | G6: 12392.84 | I6: Investimento | J6: 463 | L6: Cabelo | M6: 150
B7: Mercado | C7: 627.07 | F7: Total Geral | G7: 16956.1 | I7: Não essencial | J7: 1373 | L7: Total Geral | M7: 150
B8: Transporte | C8: 550.19 | I8: Total Geral | J8: 4563.26
B9: Educação | C9: 463
B10: Outros | C10: 402.3
B11: Beleza | C11: 150
B12: Total Geral | C12: 4563.26

Sheet TRANSAÇÕES
H1: DESPESA | I1: RECEITA | J1: CAIXA
A2: Fluxo de caixa | H2: =SUMIF(Tabela1[Caixa],TRANSAÇÕES!H1,Tabela1[Valor]) -> 4563.26 | I2: =SUMIF(Tabela1[Caixa],TRANSAÇÕES!I1,Tabela1[Valor]) -> 12392.84 | J2: =I2-H2 -> 7829.58
A3: Descrição | B3: Caixa | C3: Tag | D3: Categoria de despesa | E3: Forma de Pagamento | F3: Valor | G3: Data de Vencimento / Comprra | H3: Data do Pagamento / Compra | I3: Mês | J3: Status
A4: Aluguel | B4: Despesa | C4: Moradia | D4: =IFERROR(VLOOKUP(Tabela1[[#This Row],[Tag]],TAGS!$J$1:$K$9,2,0),"") -> Essencial | E4: Pix | F4: 950 | G4: 45268 | H4: 45268 | I4: =IF(G4="","",TEXT(G4,"mmmm")) -> dezembro | J4: =IF(Tabela1[[#This Row],[Caixa]]="Receita","Recebido",IF(G4="","",IF(H4="","",IF(H4>G4,"Pago atrasado",IF(H4<=G4,"Pago","Aguardando"))))) -> Pago
A5: Condomínio | B5: Despesa | C5: Moradia | D5: =IFERROR(VLOOKUP(Tabela1[[#This Row],[Tag]],TAGS!$J$1:$K$9,2,0),"") -> Essencial | E5: Boleto | F5: 200 | G5: 45270 | H5: 45268 | I5: =IF(G5="","",TEXT(G5,"mmmm")) -> dezembro | J5: =IF(Tabela1[[#This Row],[Caixa]]="Receita","Recebido",IF(G5="","",IF(H5="","",IF(H5>G5,"Pago atrasado",IF(H5<=G5,"Pago","Aguardando"))))) -> Pago
A6: Luz | B6: Despesa | C6: Moradia | D6: =IFERROR(VLOOKUP(Tabela1[[#This Row],[Tag]],TAGS!$J$1:$K$9,2,0),"") -> Essencial | E6: Boleto | F6: 124 | G6: 45275 | H6: 45268 | I6: =IF(G6="","",TEXT(G6,"mmmm")) -> dezembro | J6: =IF(Tabela1[[#This Row],[Caixa]]="Receita","Recebido",IF(G6="","",IF(H6="","",IF(H6>G6,"Pago atrasado",IF(H6<=G6,"Pago","Aguardando"))))) -> Pago
A7: Internet | B7: Despesa | C7: Moradia | D7: =IFERROR(VLOOKUP(Tabela1[[#This Row],[Tag]],TAGS!$J$1:$K$9,2,0),"") -> Essencial | E7: Boleto | F7: 120 | G7: 45275 | H7: 45268 | I7: =IF(G7="","",TEXT(G7,"mmmm")) -> dezembro | J7: =IF(Tabela1[[#This Row],[Caixa]]="Receita","Recebido",IF(G7="","",IF(H7="","",IF(H7>G7,"Pago atrasado",IF(H7<=G7,"Pago","Aguardando"))))) -> Pago
A8: Posto | B8: Despesa | C8: Lazer | D8: =IFERROR(VLOOKUP(Tabela1[[#This Row],[Tag]],TAGS!$J$1:$K$9,2,0),"") -> Não essencial | E8: Débito | F8: 41 | G8: 45261 | H8: 45261 | I8: =IF(G8="","",TEXT(G8,"mmmm")) -> dezembro | J8: =IF(Tabela1[[#This Row],[Caixa]]="Receita","Recebido",IF(G8="","",IF(H8="","",IF(H8>G8,"Pago atrasado",IF(H8<=G8,"Pago","Aguardando"))))) -> Pago
A9: Posto | B9: Despesa | C9: Lazer | D9: =IFERROR(VLOOKUP(Tabela1[[#This Row],[Tag]],TAGS!$J$1:$K$9,2,0),"") -> Não essencial | E9: Débito | F9: 5.99 | G9: 45261 | H9: 45261 | I9: =IF(G9="","",TEXT(G9,"mmmm")) -> dezembro | J9: =IF(Tabela1[[#This Row],[Caixa]]="Receita","Recebido",IF(G9="","",IF(H9="","",IF(H9>G9,"Pago atrasado",IF(H9<=G9,"Pago","Aguardando"))))) -> Pago
A10: Pop | B10: Despesa | C10: Transporte | D10: =IFERROR(VLOOKUP(Tabela1[[#This Row],[Tag]],TAGS!$J$1:$K$9,2,0),"") -> Essencial | E10: Débito | F10: 18.5 | G10: 45261 | H10: 45261 | I10: =IF(G10="","",TEXT(G10,"mmmm")) -> dezembro | J10: =IF(Tabela1[[#This Row],[Caixa]]="Receita","Recebido",IF(G10="","",IF(H10="","",IF(H10>G10,"Pago atrasado",IF(H10<=G10,"Pago","Aguardando"))))) -> Pago
A11: Pop | B11: Despesa | C11: Transporte | D11: =IFERROR(VLOOKUP(Tabela1[[#This Row],[Tag]],TAGS!$J$1:$K$9,2,0),"") -> Essencial | E11: Débito | F11: 18.28 | G11: 45261 | H11: 45261 | I11: =IF(G11="","",TEXT(G11,"mmmm")) -> dezembro | J11: =IF(Tabela1[[#This Row],[Caixa]]="Receita","Recebido",IF(G11="","",IF(H11="","",IF(H11>G11,"Pago atrasado",IF(H11<=G11,"Pago","Aguardando"))))) -> Pago
A12: Hot dog | B12: Despesa | C12: Lazer | D12: =IFERROR(VLOOKUP(Tabela1[[#This Row],[Tag]],TAGS!$J$1:$K$9,2,0),"") -> Não essencial | E12: Débito | F12: 12 | G12: 45261 | H12: 45261 | I12: =IF(G12="","",TEXT(G12,"mmmm")) -> dezembro | J12: =IF(Tabela1[[#This Row],[Caixa]]="Receita","Recebido",IF(G12="","",IF(H12="","",IF(H12>G12,"Pago atrasado",IF(H12<=G12,"Pago","Aguardando"))))) -> Pago
A13: OPA Bier | B13: Despesa | C13: Lazer | D13: =IFERROR(VLOOKUP(Tabela1[[#This Row],[Tag]],TAGS!$J$1:$K$9,2,0),"") -> Não essencial | E13: Débito | F13: 30 | G13: 45264 | H13: 45264 | I13: =IF(G13="","",TEXT(G13,"mmmm")) -> dezembro | J13: =IF(Tabela1[[#This Row],[Caixa]]="Receita","Recebido",IF(G13="","",IF(H13="","",IF(H13>G13,"Pago atrasado",IF(H13<=G13,"Pago","Aguardando"))))) -> Pago
A14: OPA Bier | B14: Despesa | C14: Lazer | D14: =IFERROR(VLOOKUP(Tabela1[[#This Row],[Tag]],TAGS!$J$1:$K$9,2,0),"") -> Não essencial | E14: Débito | F14: 20 | G14: 45264 | H14: 45264 | I14: =IF(G14="","",TEXT(G14,"mmmm")) -> dezembro | J14: =IF(Tabela1[[#This Row],[Caixa]]="Receita","Recebido",IF(G14="","",IF(H14="","",IF(H14>G14,"Pago atrasado",IF(H14<=G14,"Pago","Aguardando"))))) -> Pago
A15: Posto | B15: Despesa | C15: Lazer | D15: =IFERROR(VLOOKUP(Tabela1[[#This Row],[Tag]],TAGS!$J$1:$K$9,2,0),"") -> Não essencial | E15: Débito | F15: 11.9 | G15: 45264 | H15: 45264 | I15: =IF(G15="","",TEXT(G15,"mmmm")) -> dezembro | J15: =IF(Tabela1[[#This Row],[Caixa]]="Receita","Recebido",IF(G15="","",IF(H15="","",IF(H15>G15,"Pago atrasado",IF(H15<=G15,"Pago","Aguardando"))))) -> Pago
... A86: Posto | B86: Despesa | C86: Lazer | D86: =IFERROR(VLOOKUP(Tabela1[[#This Row],[Tag]],TAGS!$J$1:$K$9,2,0),"") -> Não essencial | E86: Débito | F86: 18.97 | G86: 45280 | H86: 45280 | I86: =IF(G86="","",TEXT(G86,"mmmm")) -> dezembro | J86: =IF(Tabela1[[#This Row],[Caixa]]="Receita","Recebido",IF(G86="","",IF(H86="","",IF(H86>G86,"Pago atrasado",IF(H86<=G86,"Pago","Aguardando"))))) -> Pago
A87: Pagode | B87: Receita | C87: Salário | D87: =IFERROR(VLOOKUP(Tabela1[[#This Row],[Tag]],TAGS!$J$1:$K$9,2,0),"") | E87: Next | F87: 2262 | I87: =IF(G87="","",TEXT(G87,"mmmm")) | J87: =IF(Tabela1[[#This Row],[Caixa]]="Receita","Recebido",IF(G87="","",IF(H87="","",IF(H87>G87,"Pago atrasado",IF(H87<=G87,"Pago","Aguardando"))))) -> Recebido
A88: 13º | B88: Receita | C88: Salário | D88: =IFERROR(VLOOKUP(Tabela1[[#This Row],[Tag]],TAGS!$J$1:$K$9,2,0),"") | E88: Next | F88: 1752 | I88: =IF(G88="","",TEXT(G88,"mmmm")) | J88: =IF(Tabela1[[#This Row],[Caixa]]="Receita","Recebido",IF(G88="","",IF(H88="","",IF(H88>G88,"Pago atrasado",IF(H88<=G88,"Pago","Aguardando"))))) -> Recebido
A89: Pagode | B89: Receita | C89: Salário | D89: =IFERROR(VLOOKUP(Tabela1[[#This Row],[Tag]],TAGS!$J$1:$K$9,2,0),"") | E89: Next | F89: 500 | I89: =IF(G89="","",TEXT(G89,"mmmm")) | J89: =IF(Tabela1[[#This Row],[Caixa]]="Receita","Recebido",IF(G89="","",IF(H89="","",IF(H89>G89,"Pago atrasado",IF(H89<=G89,"Pago","Aguardando"))))) -> Recebido
A90: Férias | B90: Receita | C90: Salário | D90: =IFERROR(VLOOKUP(Tabela1[[#This Row],[Tag]],TAGS!$J$1:$K$9,2,0),"") | E90: Next | F90: 7164 | I90: =IF(G90="","",TEXT(G90,"mmmm")) | J90: =IF(Tabela1[[#This Row],[Caixa]]="Receita","Recebido",IF(G90="","",IF(H90="","",IF(H90>G90,"Pago atrasado",IF(H90<=G90,"Pago","Aguardando"))))) -> Recebido
A91: Pop | B91: Despesa | C91: Transporte | D91: =IFERROR(VLOOKUP(Tabela1[[#This Row],[Tag]],TAGS!$J$1:$K$9,2,0),"") -> Essencial | E91: Débito | F91: 13.6 | G91: 45281 | H91: 45281 | I91: =IF(G91="","",TEXT(G91,"mmmm")) -> dezembro | J91: =IF(Tabela1[[#This Row],[Caixa]]="Receita","Recebido",IF(G91="","",IF(H91="","",IF(H91>G91,"Pago atrasado",IF(H91<=G91,"Pago","Aguardando"))))) -> Pago
A92: Posto | B92: Despesa | C92: Lazer | D92: =IFERROR(VLOOKUP(Tabela1[[#This Row],[Tag]],TAGS!$J$1:$K$9,2,0),"") -> Não essencial | E92: Débito | F92: 29.96 | G92: 45281 | H92: 45281 | I92: =IF(G92="","",TEXT(G92,"mmmm")) -> dezembro | J92: =IF(Tabela1[[#This Row],[Caixa]]="Receita","Recebido",IF(G92="","",IF(H92="","",IF(H92>G92,"Pago atrasado",IF(H92<=G92,"Pago","Aguardando"))))) -> Pago
A93: Cooper | B93: Despesa | C93: Mercado | D93: =IFERROR(VLOOKUP(Tabela1[[#This Row],[Tag]],TAGS!$J$1:$K$9,2,0),"") -> Essencial | E93: Débito | F93: 11.56 | G93: 45281 | H93: 45281 | I93: =IF(G93="","",TEXT(G93,"mmmm")) -> dezembro | J93: =IF(Tabela1[[#This Row],[Caixa]]="Receita","Recebido",IF(G93="","",IF(H93="","",IF(H93>G93,"Pago atrasado",IF(H93<=G93,"Pago","Aguardando"))))) -> Pago
A94: Cooper | B94: Despesa | C94: Mercado | D94: =IFERROR(VLOOKUP(Tabela1[[#This Row],[Tag]],TAGS!$J$1:$K$9,2,0),"") -> Essencial | E94: Débito | F94: 68.06 | G94: 45281 | H94: 45281 | I94: =IF(G94="","",TEXT(G94,"mmmm")) -> dezembro | J94: =IF(Tabela1[[#This Row],[Caixa]]="Receita","Recebido",IF(G94="","",IF(H94="","",IF(H94>G94,"Pago atrasado",IF(H94<=G94,"Pago","Aguardando"))))) -> Pago
A95: Cooper | B95: Despesa | C95: Mercado | D95: =IFERROR(VLOOKUP(Tabela1[[#This Row],[Tag]],TAGS!$J$1:$K$9,2,0),"") -> Essencial | E95: Débito | F95: 6.39 | G95: 45281 | H95: 45281 | I95: =IF(G95="","",TEXT(G95,"mmmm")) -> dezembro | J95: =IF(Tabela1[[#This Row],[Caixa]]="Receita","Recebido",IF(G95="","",IF(H95="","",IF(H95>G95,"Pago atrasado",IF(H95<=G95,"Pago","Aguardando"))))) -> Pago
A96: Pop | B96: Despesa | C96: Transporte | D96: =IFERROR(VLOOKUP(Tabela1[[#This Row],[Tag]],TAGS!$J$1:$K$9,2,0),"") -> Essencial | E96: Débito | F96: 12.7 | G96: 45281 | H96: 45281 | I96: =IF(G96="","",TEXT(G96,"mmmm")) -> dezembro | J96: =IF(Tabela1[[#This Row],[Caixa]]="Receita","Recebido",IF(G96="","",IF(H96="","",IF(H96>G96,"Pago atrasado",IF(H96<=G96,"Pago","Aguardando"))))) -> Pago
A97: Toninho | B97: Despesa | C97: Lazer | D97: =IFERROR(VLOOKUP(Tabela1[[#This Row],[Tag]],TAGS!$J$1:$K$9,2,0),"") -> Não essencial | E97: Débito | F97: 18 | G97: 45281 | H97: 45281 | I97: =IF(G97="","",TEXT(G97,"mmmm")) -> dezembro | J97: =IF(Tabela1[[#This Row],[Caixa]]="Receita","Recebido",IF(G97="","",IF(H97="","",IF(H97>G97,"Pago atrasado",IF(H97<=G97,"Pago","Aguardando"))))) -> Pago
A98: Burger King | B98: Despesa | C98: Lazer | D98: =IFERROR(VLOOKUP(Tabela1[[#This Row],[Tag]],TAGS!$J$1:$K$9,2,0),"") -> Não essencial | E98: Débito | F98: 4.5 | G98: 45281 | H98: 45281 | I98: =IF(G98="","",TEXT(G98,"mmmm")) -> dezembro | J98: =IF(Tabela1[[#This Row],[Caixa]]="Receita","Recebido",IF(G98="","",IF(H98="","",IF(H98>G98,"Pago atrasado",IF(H98<=G98,"Pago","Aguardando"))))) -> Pago
A99: Pop | B99: Despesa | C99: Transporte | D99: =IFERROR(VLOOKUP(Tabela1[[#This Row],[Tag]],TAGS!$J$1:$K$9,2,0),"") -> Essencial | E99: Débito | F99: 18.12 | G99: 45281 | H99: 45281 | I99: =IF(G99="","",TEXT(G99,"mmmm")) -> dezembro | J99: =IF(Tabela1[[#This Row],[Caixa]]="Receita","Recebido",IF(G99="","",IF(H99="","",IF(H99>G99,"Pago atrasado",IF(H99<=G99,"Pago","Aguardando"))))) -> Pago
A100: Uber | B100: Despesa | C100: Transporte | D100: =IFERROR(VLOOKUP(Tabela1[[#This Row],[Tag]],TAGS!$J$1:$K$9,2,0),"") -> Essencial | E100: Débito | F100: 22.5 | G100: 45281 | H100: 45281 | I100: =IF(G100="","",TEXT(G100,"mmmm")) -> dezembro | J100: =IF(Tabela1[[#This Row],[Caixa]]="Receita","Recebido",IF(G100="","",IF(H100="","",IF(H100>G100,"Pago atrasado",IF(H100<=G100,"Pago","Aguardando"))))) -> Pago
A101: Presente Iza | B101: Despesa | C101: Outros | D101: =IFERROR(VLOOKUP(Tabela1[[#This Row],[Tag]],TAGS!$J$1:$K$9,2,0),"") -> Não essencial | E101: Débito | F101: 60 | G101: 45281 | H101: 45281 | I101: =IF(G101="","",TEXT(G101,"mmmm")) -> dezembro | J101: =IF(Tabela1[[#This Row],[Caixa]]="Receita","Recebido",IF(G101="","",IF(H101="","",IF(H101>G101,"Pago atrasado",IF(H101<=G101,"Pago","Aguardando"))))) -> Pago
A102: Cooper | B102: Despesa | C102: Mercado | D102: =IFERROR(VLOOKUP(Tabela1[[#This Row],[Tag]],TAGS!$J$1:$K$9,2,0),"") -> Essencial | E102: Débito | F102: 55.82 | G102: 45281 | H102: 45281 | I102: =IF(G102="","",TEXT(G102,"mmmm")) -> dezembro | J102: =IF(Tabela1[[#This Row],[Caixa]]="Receita","Recebido",IF(G102="","",IF(H102="","",IF(H102>G102,"Pago atrasado",IF(H102<=G102,"Pago","Aguardando"))))) -> Pago
... A108: Angeloni | B108: Despesa | C108: Mercado | D108: =IFERROR(VLOOKUP(Tabela1[[#This Row],[Tag]],TAGS!$J$1:$K$9,2,0),"") -> Essencial | E108: Débito | F108: 17 | G108: 45281 | H108: 45281 | I108: =IF(G108="","",TEXT(G108,"mmmm")) -> dezembro | J108: =IF(Tabela1[[#This Row],[Caixa]]="Receita","Recebido",IF(G108="","",IF(H108="","",IF(H108>G108,"Pago atrasado",IF(H108<=G108,"Pago","Aguardando"))))) -> Pago
A109: Salário | B109: Receita | C109: Salário | D109: =IFERROR(VLOOKUP(Tabela1[[#This Row],[Tag]],TAGS!$J$1:$K$9,2,0),"") | E109: Next | F109: 714.84 | I109: =IF(G109="","",TEXT(G109,"mmmm")) | J109: =IF(Tabela1[[#This Row],[Caixa]]="Receita","Recebido",IF(G109="","",IF(H109="","",IF(H109>G109,"Pago atrasado",IF(H109<=G109,"Pago","Aguardando"))))) -> Recebido
A110: Toninho (Almoço) | B110: Despesa | C110: Mercado | D110: =IFERROR(VLOOKUP(Tabela1[[#This Row],[Tag]],TAGS!$J$1:$K$9,2,0),"") -> Essencial | E110: Débito | F110: 58 | G110: 45284 | H110: 45284 | I110: =IF(G110="","",TEXT(G110,"mmmm")) -> dezembro | J110: =IF(Tabela1[[#This Row],[Caixa]]="Receita","Recebido",IF(G110="","",IF(H110="","",IF(H110>G110,"Pago atrasado",IF(H110<=G110,"Pago","Aguardando"))))) -> Pago
D111: =IFERROR(VLOOKUP(Tabela1[[#This Row],[Tag]],TAGS!$J$1:$K$9,2,0),"") | I111: =IF(G111="","",TEXT(G111,"mmmm")) | J111: =IF(Tabela1[[#This Row],[Caixa]]="Receita","Recebido",IF(G111="","",IF(H111="","",IF(H111>G111,"Pago atrasado",IF(H111<=G111,"Pago","Aguardando")))))
D112: =IFERROR(VLOOKUP(Tabela1[[#This Row],[Tag]],TAGS!$J$1:$K$9,2,0),"") | I112: =IF(G112="","",TEXT(G112,"mmmm")) | J112: =IF(Tabela1[[#This Row],[Caixa]]="Receita","Recebido",IF(G112="","",IF(H112="","",IF(H112>G112,"Pago atrasado",IF(H112<=G112,"Pago","Aguardando")))))
D113: =IFERROR(VLOOKUP(Tabela1[[#This Row],[Tag]],TAGS!$J$1:$K$9,2,0),"") | I113: =IF(G113="","",TEXT(G113,"mmmm")) | J113: =IF(Tabela1[[#This Row],[Caixa]]="Receita","Recebido",IF(G113="","",IF(H113="","",IF(H113>G113,"Pago atrasado",IF(H113<=G113,"Pago","Aguardando")))))
D114: =IFERROR(VLOOKUP(Tabela1[[#This Row],[Tag]],TAGS!$J$1:$K$9,2,0),"") | I114: =IF(G114="","",TEXT(G114,"mmmm")) | J114: =IF(Tabela1[[#This Row],[Caixa]]="Receita","Recebido",IF(G114="","",IF(H114="","",IF(H114>G114,"Pago atrasado",IF(H114<=G114,"Pago","Aguardando")))))
D115: =IFERROR(VLOOKUP(Tabela1[[#This Row],[Tag]],TAGS!$J$1:$K$9,2,0),"") | I115: =IF(G115="","",TEXT(G115,"mmmm")) | J115: =IF(Tabela1[[#This Row],[Caixa]]="Receita","Recebido",IF(G115="","",IF(H115="","",IF(H115>G115,"Pago atrasado",IF(H115<=G115,"Pago","Aguardando")))))
...

Sheet TAGS
A1: Tag de Despesas | C1: Caixa | E1: Formas de pagamento | J1: Categoria de Despesa | K1: Desc
A2: Moradia | C2: Receita | E2: Débito | J2: Moradia | K2: Essencial
A3: Mercado | C3: Despesa | E3: Crédito | J3: Mercado | K3: Essencial
A4: Transporte | E4: Pix | J4: Transporte | K4: Essencial
A5: Lazer | E5: Next | J5: Lazer | K5: Não essencial
A6: Beleza | E6: Boleto | J6: Beleza | K6: Não essencial
A7: Educação | J7: Educação | K7: Investimento
A8: Outros | J8: Outros | K8: Não essencial
A9: Salário | J9: Investimento | K9: Investimento
